[2024-07-28T00:19:36.731+0000] {processor.py:161} INFO - Started process (PID=41018) to work on /opt/airflow/dags/etl_dag.py
[2024-07-28T00:19:36.733+0000] {processor.py:830} INFO - Processing file /opt/airflow/dags/etl_dag.py for tasks to queue
[2024-07-28T00:19:36.735+0000] {logging_mixin.py:188} INFO - [2024-07-28T00:19:36.734+0000] {dagbag.py:538} INFO - Filling up the DagBag from /opt/airflow/dags/etl_dag.py
[2024-07-28T00:19:36.767+0000] {logging_mixin.py:188} INFO - [2024-07-28T00:19:36.755+0000] {dagbag.py:348} ERROR - Failed to import: /opt/airflow/dags/etl_dag.py
Traceback (most recent call last):
  File "/home/airflow/.local/lib/python3.8/site-packages/airflow/models/dagbag.py", line 344, in parse
    loader.exec_module(new_module)
  File "<frozen importlib._bootstrap_external>", line 843, in exec_module
  File "<frozen importlib._bootstrap>", line 219, in _call_with_frames_removed
  File "/opt/airflow/dags/etl_dag.py", line 4, in <module>
    from airflow.providers.google.cloud.transfers.gcs_to_bigquery import GCSToBigQueryOperator
  File "/home/airflow/.local/lib/python3.8/site-packages/airflow/providers/google/cloud/transfers/gcs_to_bigquery.py", line 24, in <module>
    from airflow.providers.google.cloud.hooks.bigquery import BigQueryHook
  File "/home/airflow/.local/lib/python3.8/site-packages/airflow/providers/google/cloud/hooks/bigquery.py", line 33, in <module>
    from google.cloud.bigquery import (
  File "/home/airflow/.local/lib/python3.8/site-packages/google/cloud/bigquery/__init__.py", line 35, in <module>
    from google.cloud.bigquery.client import Client
  File "/home/airflow/.local/lib/python3.8/site-packages/google/cloud/bigquery/client.py", line 74, in <module>
    from google.cloud.bigquery import _pandas_helpers
  File "/home/airflow/.local/lib/python3.8/site-packages/google/cloud/bigquery/_pandas_helpers.py", line 56, in <module>
    _to_wkb = _to_wkb()
  File "/home/airflow/.local/lib/python3.8/site-packages/google/cloud/bigquery/_pandas_helpers.py", line 46, in _to_wkb
    from shapely.geos import WKBWriter, lgeos  # type: ignore
ImportError: cannot import name 'WKBWriter' from 'shapely.geos' (/home/airflow/.local/lib/python3.8/site-packages/shapely/geos.py)
[2024-07-28T00:19:36.769+0000] {processor.py:842} WARNING - No viable dags retrieved from /opt/airflow/dags/etl_dag.py
[2024-07-28T00:19:36.797+0000] {processor.py:183} INFO - Processing /opt/airflow/dags/etl_dag.py took 0.081 seconds
[2024-07-28T01:42:43.855+0000] {processor.py:161} INFO - Started process (PID=41023) to work on /opt/airflow/dags/etl_dag.py
[2024-07-28T01:42:43.858+0000] {processor.py:830} INFO - Processing file /opt/airflow/dags/etl_dag.py for tasks to queue
[2024-07-28T01:42:43.864+0000] {logging_mixin.py:188} INFO - [2024-07-28T01:42:43.863+0000] {dagbag.py:538} INFO - Filling up the DagBag from /opt/airflow/dags/etl_dag.py
[2024-07-28T01:42:43.889+0000] {logging_mixin.py:188} INFO - [2024-07-28T01:42:43.884+0000] {dagbag.py:348} ERROR - Failed to import: /opt/airflow/dags/etl_dag.py
Traceback (most recent call last):
  File "/home/airflow/.local/lib/python3.8/site-packages/airflow/models/dagbag.py", line 344, in parse
    loader.exec_module(new_module)
  File "<frozen importlib._bootstrap_external>", line 843, in exec_module
  File "<frozen importlib._bootstrap>", line 219, in _call_with_frames_removed
  File "/opt/airflow/dags/etl_dag.py", line 4, in <module>
    from airflow.providers.google.cloud.transfers.gcs_to_bigquery import GCSToBigQueryOperator
  File "/home/airflow/.local/lib/python3.8/site-packages/airflow/providers/google/cloud/transfers/gcs_to_bigquery.py", line 24, in <module>
    from airflow.providers.google.cloud.hooks.bigquery import BigQueryHook
  File "/home/airflow/.local/lib/python3.8/site-packages/airflow/providers/google/cloud/hooks/bigquery.py", line 33, in <module>
    from google.cloud.bigquery import (
  File "/home/airflow/.local/lib/python3.8/site-packages/google/cloud/bigquery/__init__.py", line 35, in <module>
    from google.cloud.bigquery.client import Client
  File "/home/airflow/.local/lib/python3.8/site-packages/google/cloud/bigquery/client.py", line 74, in <module>
    from google.cloud.bigquery import _pandas_helpers
  File "/home/airflow/.local/lib/python3.8/site-packages/google/cloud/bigquery/_pandas_helpers.py", line 56, in <module>
    _to_wkb = _to_wkb()
  File "/home/airflow/.local/lib/python3.8/site-packages/google/cloud/bigquery/_pandas_helpers.py", line 46, in _to_wkb
    from shapely.geos import WKBWriter, lgeos  # type: ignore
ImportError: cannot import name 'WKBWriter' from 'shapely.geos' (/home/airflow/.local/lib/python3.8/site-packages/shapely/geos.py)
[2024-07-28T01:42:43.891+0000] {processor.py:842} WARNING - No viable dags retrieved from /opt/airflow/dags/etl_dag.py
[2024-07-28T01:42:43.950+0000] {processor.py:183} INFO - Processing /opt/airflow/dags/etl_dag.py took 0.100 seconds
[2024-07-28T03:21:30.634+0000] {processor.py:161} INFO - Started process (PID=41028) to work on /opt/airflow/dags/etl_dag.py
[2024-07-28T03:21:30.636+0000] {processor.py:830} INFO - Processing file /opt/airflow/dags/etl_dag.py for tasks to queue
[2024-07-28T03:21:30.637+0000] {logging_mixin.py:188} INFO - [2024-07-28T03:21:30.637+0000] {dagbag.py:538} INFO - Filling up the DagBag from /opt/airflow/dags/etl_dag.py
[2024-07-28T03:21:30.677+0000] {logging_mixin.py:188} INFO - [2024-07-28T03:21:30.671+0000] {dagbag.py:348} ERROR - Failed to import: /opt/airflow/dags/etl_dag.py
Traceback (most recent call last):
  File "/home/airflow/.local/lib/python3.8/site-packages/airflow/models/dagbag.py", line 344, in parse
    loader.exec_module(new_module)
  File "<frozen importlib._bootstrap_external>", line 843, in exec_module
  File "<frozen importlib._bootstrap>", line 219, in _call_with_frames_removed
  File "/opt/airflow/dags/etl_dag.py", line 4, in <module>
    from airflow.providers.google.cloud.transfers.gcs_to_bigquery import GCSToBigQueryOperator
  File "/home/airflow/.local/lib/python3.8/site-packages/airflow/providers/google/cloud/transfers/gcs_to_bigquery.py", line 24, in <module>
    from airflow.providers.google.cloud.hooks.bigquery import BigQueryHook
  File "/home/airflow/.local/lib/python3.8/site-packages/airflow/providers/google/cloud/hooks/bigquery.py", line 33, in <module>
    from google.cloud.bigquery import (
  File "/home/airflow/.local/lib/python3.8/site-packages/google/cloud/bigquery/__init__.py", line 35, in <module>
    from google.cloud.bigquery.client import Client
  File "/home/airflow/.local/lib/python3.8/site-packages/google/cloud/bigquery/client.py", line 74, in <module>
    from google.cloud.bigquery import _pandas_helpers
  File "/home/airflow/.local/lib/python3.8/site-packages/google/cloud/bigquery/_pandas_helpers.py", line 56, in <module>
    _to_wkb = _to_wkb()
  File "/home/airflow/.local/lib/python3.8/site-packages/google/cloud/bigquery/_pandas_helpers.py", line 46, in _to_wkb
    from shapely.geos import WKBWriter, lgeos  # type: ignore
ImportError: cannot import name 'WKBWriter' from 'shapely.geos' (/home/airflow/.local/lib/python3.8/site-packages/shapely/geos.py)
[2024-07-28T03:21:30.678+0000] {processor.py:842} WARNING - No viable dags retrieved from /opt/airflow/dags/etl_dag.py
[2024-07-28T03:21:30.738+0000] {processor.py:183} INFO - Processing /opt/airflow/dags/etl_dag.py took 0.109 seconds
[2024-07-28T04:27:36.332+0000] {processor.py:161} INFO - Started process (PID=41035) to work on /opt/airflow/dags/etl_dag.py
[2024-07-28T04:27:36.337+0000] {processor.py:830} INFO - Processing file /opt/airflow/dags/etl_dag.py for tasks to queue
[2024-07-28T04:27:36.342+0000] {logging_mixin.py:188} INFO - [2024-07-28T04:27:36.341+0000] {dagbag.py:538} INFO - Filling up the DagBag from /opt/airflow/dags/etl_dag.py
[2024-07-28T04:27:36.363+0000] {logging_mixin.py:188} INFO - [2024-07-28T04:27:36.359+0000] {dagbag.py:348} ERROR - Failed to import: /opt/airflow/dags/etl_dag.py
Traceback (most recent call last):
  File "/home/airflow/.local/lib/python3.8/site-packages/airflow/models/dagbag.py", line 344, in parse
    loader.exec_module(new_module)
  File "<frozen importlib._bootstrap_external>", line 843, in exec_module
  File "<frozen importlib._bootstrap>", line 219, in _call_with_frames_removed
  File "/opt/airflow/dags/etl_dag.py", line 4, in <module>
    from airflow.providers.google.cloud.transfers.gcs_to_bigquery import GCSToBigQueryOperator
  File "/home/airflow/.local/lib/python3.8/site-packages/airflow/providers/google/cloud/transfers/gcs_to_bigquery.py", line 24, in <module>
    from airflow.providers.google.cloud.hooks.bigquery import BigQueryHook
  File "/home/airflow/.local/lib/python3.8/site-packages/airflow/providers/google/cloud/hooks/bigquery.py", line 33, in <module>
    from google.cloud.bigquery import (
  File "/home/airflow/.local/lib/python3.8/site-packages/google/cloud/bigquery/__init__.py", line 35, in <module>
    from google.cloud.bigquery.client import Client
  File "/home/airflow/.local/lib/python3.8/site-packages/google/cloud/bigquery/client.py", line 74, in <module>
    from google.cloud.bigquery import _pandas_helpers
  File "/home/airflow/.local/lib/python3.8/site-packages/google/cloud/bigquery/_pandas_helpers.py", line 56, in <module>
    _to_wkb = _to_wkb()
  File "/home/airflow/.local/lib/python3.8/site-packages/google/cloud/bigquery/_pandas_helpers.py", line 46, in _to_wkb
    from shapely.geos import WKBWriter, lgeos  # type: ignore
ImportError: cannot import name 'WKBWriter' from 'shapely.geos' (/home/airflow/.local/lib/python3.8/site-packages/shapely/geos.py)
[2024-07-28T04:27:36.368+0000] {processor.py:842} WARNING - No viable dags retrieved from /opt/airflow/dags/etl_dag.py
[2024-07-28T04:27:36.420+0000] {processor.py:183} INFO - Processing /opt/airflow/dags/etl_dag.py took 0.094 seconds
[2024-07-28T05:49:44.429+0000] {processor.py:161} INFO - Started process (PID=41040) to work on /opt/airflow/dags/etl_dag.py
[2024-07-28T05:49:44.431+0000] {processor.py:830} INFO - Processing file /opt/airflow/dags/etl_dag.py for tasks to queue
[2024-07-28T05:49:44.436+0000] {logging_mixin.py:188} INFO - [2024-07-28T05:49:44.435+0000] {dagbag.py:538} INFO - Filling up the DagBag from /opt/airflow/dags/etl_dag.py
[2024-07-28T05:49:44.455+0000] {logging_mixin.py:188} INFO - [2024-07-28T05:49:44.452+0000] {dagbag.py:348} ERROR - Failed to import: /opt/airflow/dags/etl_dag.py
Traceback (most recent call last):
  File "/home/airflow/.local/lib/python3.8/site-packages/airflow/models/dagbag.py", line 344, in parse
    loader.exec_module(new_module)
  File "<frozen importlib._bootstrap_external>", line 843, in exec_module
  File "<frozen importlib._bootstrap>", line 219, in _call_with_frames_removed
  File "/opt/airflow/dags/etl_dag.py", line 4, in <module>
    from airflow.providers.google.cloud.transfers.gcs_to_bigquery import GCSToBigQueryOperator
  File "/home/airflow/.local/lib/python3.8/site-packages/airflow/providers/google/cloud/transfers/gcs_to_bigquery.py", line 24, in <module>
    from airflow.providers.google.cloud.hooks.bigquery import BigQueryHook
  File "/home/airflow/.local/lib/python3.8/site-packages/airflow/providers/google/cloud/hooks/bigquery.py", line 33, in <module>
    from google.cloud.bigquery import (
  File "/home/airflow/.local/lib/python3.8/site-packages/google/cloud/bigquery/__init__.py", line 35, in <module>
    from google.cloud.bigquery.client import Client
  File "/home/airflow/.local/lib/python3.8/site-packages/google/cloud/bigquery/client.py", line 74, in <module>
    from google.cloud.bigquery import _pandas_helpers
  File "/home/airflow/.local/lib/python3.8/site-packages/google/cloud/bigquery/_pandas_helpers.py", line 56, in <module>
    _to_wkb = _to_wkb()
  File "/home/airflow/.local/lib/python3.8/site-packages/google/cloud/bigquery/_pandas_helpers.py", line 46, in _to_wkb
    from shapely.geos import WKBWriter, lgeos  # type: ignore
ImportError: cannot import name 'WKBWriter' from 'shapely.geos' (/home/airflow/.local/lib/python3.8/site-packages/shapely/geos.py)
[2024-07-28T05:49:44.457+0000] {processor.py:842} WARNING - No viable dags retrieved from /opt/airflow/dags/etl_dag.py
[2024-07-28T05:49:44.472+0000] {processor.py:183} INFO - Processing /opt/airflow/dags/etl_dag.py took 0.048 seconds
[2024-07-28T06:43:58.729+0000] {processor.py:161} INFO - Started process (PID=41045) to work on /opt/airflow/dags/etl_dag.py
[2024-07-28T06:43:58.734+0000] {processor.py:830} INFO - Processing file /opt/airflow/dags/etl_dag.py for tasks to queue
[2024-07-28T06:43:58.739+0000] {logging_mixin.py:188} INFO - [2024-07-28T06:43:58.738+0000] {dagbag.py:538} INFO - Filling up the DagBag from /opt/airflow/dags/etl_dag.py
[2024-07-28T06:43:58.759+0000] {logging_mixin.py:188} INFO - [2024-07-28T06:43:58.755+0000] {dagbag.py:348} ERROR - Failed to import: /opt/airflow/dags/etl_dag.py
Traceback (most recent call last):
  File "/home/airflow/.local/lib/python3.8/site-packages/airflow/models/dagbag.py", line 344, in parse
    loader.exec_module(new_module)
  File "<frozen importlib._bootstrap_external>", line 843, in exec_module
  File "<frozen importlib._bootstrap>", line 219, in _call_with_frames_removed
  File "/opt/airflow/dags/etl_dag.py", line 4, in <module>
    from airflow.providers.google.cloud.transfers.gcs_to_bigquery import GCSToBigQueryOperator
  File "/home/airflow/.local/lib/python3.8/site-packages/airflow/providers/google/cloud/transfers/gcs_to_bigquery.py", line 24, in <module>
    from airflow.providers.google.cloud.hooks.bigquery import BigQueryHook
  File "/home/airflow/.local/lib/python3.8/site-packages/airflow/providers/google/cloud/hooks/bigquery.py", line 33, in <module>
    from google.cloud.bigquery import (
  File "/home/airflow/.local/lib/python3.8/site-packages/google/cloud/bigquery/__init__.py", line 35, in <module>
    from google.cloud.bigquery.client import Client
  File "/home/airflow/.local/lib/python3.8/site-packages/google/cloud/bigquery/client.py", line 74, in <module>
    from google.cloud.bigquery import _pandas_helpers
  File "/home/airflow/.local/lib/python3.8/site-packages/google/cloud/bigquery/_pandas_helpers.py", line 56, in <module>
    _to_wkb = _to_wkb()
  File "/home/airflow/.local/lib/python3.8/site-packages/google/cloud/bigquery/_pandas_helpers.py", line 46, in _to_wkb
    from shapely.geos import WKBWriter, lgeos  # type: ignore
ImportError: cannot import name 'WKBWriter' from 'shapely.geos' (/home/airflow/.local/lib/python3.8/site-packages/shapely/geos.py)
[2024-07-28T06:43:58.765+0000] {processor.py:842} WARNING - No viable dags retrieved from /opt/airflow/dags/etl_dag.py
[2024-07-28T06:43:58.798+0000] {processor.py:183} INFO - Processing /opt/airflow/dags/etl_dag.py took 0.072 seconds
[2024-07-28T07:51:13.335+0000] {processor.py:161} INFO - Started process (PID=41050) to work on /opt/airflow/dags/etl_dag.py
[2024-07-28T07:51:13.338+0000] {processor.py:830} INFO - Processing file /opt/airflow/dags/etl_dag.py for tasks to queue
[2024-07-28T07:51:13.342+0000] {logging_mixin.py:188} INFO - [2024-07-28T07:51:13.342+0000] {dagbag.py:538} INFO - Filling up the DagBag from /opt/airflow/dags/etl_dag.py
[2024-07-28T07:51:13.356+0000] {logging_mixin.py:188} INFO - [2024-07-28T07:51:13.353+0000] {dagbag.py:348} ERROR - Failed to import: /opt/airflow/dags/etl_dag.py
Traceback (most recent call last):
  File "/home/airflow/.local/lib/python3.8/site-packages/airflow/models/dagbag.py", line 344, in parse
    loader.exec_module(new_module)
  File "<frozen importlib._bootstrap_external>", line 843, in exec_module
  File "<frozen importlib._bootstrap>", line 219, in _call_with_frames_removed
  File "/opt/airflow/dags/etl_dag.py", line 4, in <module>
    from airflow.providers.google.cloud.transfers.gcs_to_bigquery import GCSToBigQueryOperator
  File "/home/airflow/.local/lib/python3.8/site-packages/airflow/providers/google/cloud/transfers/gcs_to_bigquery.py", line 24, in <module>
    from airflow.providers.google.cloud.hooks.bigquery import BigQueryHook
  File "/home/airflow/.local/lib/python3.8/site-packages/airflow/providers/google/cloud/hooks/bigquery.py", line 33, in <module>
    from google.cloud.bigquery import (
  File "/home/airflow/.local/lib/python3.8/site-packages/google/cloud/bigquery/__init__.py", line 35, in <module>
    from google.cloud.bigquery.client import Client
  File "/home/airflow/.local/lib/python3.8/site-packages/google/cloud/bigquery/client.py", line 74, in <module>
    from google.cloud.bigquery import _pandas_helpers
  File "/home/airflow/.local/lib/python3.8/site-packages/google/cloud/bigquery/_pandas_helpers.py", line 56, in <module>
    _to_wkb = _to_wkb()
  File "/home/airflow/.local/lib/python3.8/site-packages/google/cloud/bigquery/_pandas_helpers.py", line 46, in _to_wkb
    from shapely.geos import WKBWriter, lgeos  # type: ignore
ImportError: cannot import name 'WKBWriter' from 'shapely.geos' (/home/airflow/.local/lib/python3.8/site-packages/shapely/geos.py)
[2024-07-28T07:51:13.358+0000] {processor.py:842} WARNING - No viable dags retrieved from /opt/airflow/dags/etl_dag.py
[2024-07-28T07:51:13.376+0000] {processor.py:183} INFO - Processing /opt/airflow/dags/etl_dag.py took 0.044 seconds
[2024-07-28T09:16:34.446+0000] {processor.py:161} INFO - Started process (PID=41057) to work on /opt/airflow/dags/etl_dag.py
[2024-07-28T09:16:34.448+0000] {processor.py:830} INFO - Processing file /opt/airflow/dags/etl_dag.py for tasks to queue
[2024-07-28T09:16:34.451+0000] {logging_mixin.py:188} INFO - [2024-07-28T09:16:34.449+0000] {dagbag.py:538} INFO - Filling up the DagBag from /opt/airflow/dags/etl_dag.py
[2024-07-28T09:16:34.480+0000] {logging_mixin.py:188} INFO - [2024-07-28T09:16:34.473+0000] {dagbag.py:348} ERROR - Failed to import: /opt/airflow/dags/etl_dag.py
Traceback (most recent call last):
  File "/home/airflow/.local/lib/python3.8/site-packages/airflow/models/dagbag.py", line 344, in parse
    loader.exec_module(new_module)
  File "<frozen importlib._bootstrap_external>", line 843, in exec_module
  File "<frozen importlib._bootstrap>", line 219, in _call_with_frames_removed
  File "/opt/airflow/dags/etl_dag.py", line 4, in <module>
    from airflow.providers.google.cloud.transfers.gcs_to_bigquery import GCSToBigQueryOperator
  File "/home/airflow/.local/lib/python3.8/site-packages/airflow/providers/google/cloud/transfers/gcs_to_bigquery.py", line 24, in <module>
    from airflow.providers.google.cloud.hooks.bigquery import BigQueryHook
  File "/home/airflow/.local/lib/python3.8/site-packages/airflow/providers/google/cloud/hooks/bigquery.py", line 33, in <module>
    from google.cloud.bigquery import (
  File "/home/airflow/.local/lib/python3.8/site-packages/google/cloud/bigquery/__init__.py", line 35, in <module>
    from google.cloud.bigquery.client import Client
  File "/home/airflow/.local/lib/python3.8/site-packages/google/cloud/bigquery/client.py", line 74, in <module>
    from google.cloud.bigquery import _pandas_helpers
  File "/home/airflow/.local/lib/python3.8/site-packages/google/cloud/bigquery/_pandas_helpers.py", line 56, in <module>
    _to_wkb = _to_wkb()
  File "/home/airflow/.local/lib/python3.8/site-packages/google/cloud/bigquery/_pandas_helpers.py", line 46, in _to_wkb
    from shapely.geos import WKBWriter, lgeos  # type: ignore
ImportError: cannot import name 'WKBWriter' from 'shapely.geos' (/home/airflow/.local/lib/python3.8/site-packages/shapely/geos.py)
[2024-07-28T09:16:34.481+0000] {processor.py:842} WARNING - No viable dags retrieved from /opt/airflow/dags/etl_dag.py
[2024-07-28T09:16:34.517+0000] {processor.py:183} INFO - Processing /opt/airflow/dags/etl_dag.py took 0.081 seconds
[2024-07-28T10:56:29.394+0000] {processor.py:161} INFO - Started process (PID=41062) to work on /opt/airflow/dags/etl_dag.py
[2024-07-28T10:56:29.400+0000] {processor.py:830} INFO - Processing file /opt/airflow/dags/etl_dag.py for tasks to queue
[2024-07-28T10:56:29.408+0000] {logging_mixin.py:188} INFO - [2024-07-28T10:56:29.406+0000] {dagbag.py:538} INFO - Filling up the DagBag from /opt/airflow/dags/etl_dag.py
[2024-07-28T10:56:29.430+0000] {logging_mixin.py:188} INFO - [2024-07-28T10:56:29.424+0000] {dagbag.py:348} ERROR - Failed to import: /opt/airflow/dags/etl_dag.py
Traceback (most recent call last):
  File "/home/airflow/.local/lib/python3.8/site-packages/airflow/models/dagbag.py", line 344, in parse
    loader.exec_module(new_module)
  File "<frozen importlib._bootstrap_external>", line 843, in exec_module
  File "<frozen importlib._bootstrap>", line 219, in _call_with_frames_removed
  File "/opt/airflow/dags/etl_dag.py", line 4, in <module>
    from airflow.providers.google.cloud.transfers.gcs_to_bigquery import GCSToBigQueryOperator
  File "/home/airflow/.local/lib/python3.8/site-packages/airflow/providers/google/cloud/transfers/gcs_to_bigquery.py", line 24, in <module>
    from airflow.providers.google.cloud.hooks.bigquery import BigQueryHook
  File "/home/airflow/.local/lib/python3.8/site-packages/airflow/providers/google/cloud/hooks/bigquery.py", line 33, in <module>
    from google.cloud.bigquery import (
  File "/home/airflow/.local/lib/python3.8/site-packages/google/cloud/bigquery/__init__.py", line 35, in <module>
    from google.cloud.bigquery.client import Client
  File "/home/airflow/.local/lib/python3.8/site-packages/google/cloud/bigquery/client.py", line 74, in <module>
    from google.cloud.bigquery import _pandas_helpers
  File "/home/airflow/.local/lib/python3.8/site-packages/google/cloud/bigquery/_pandas_helpers.py", line 56, in <module>
    _to_wkb = _to_wkb()
  File "/home/airflow/.local/lib/python3.8/site-packages/google/cloud/bigquery/_pandas_helpers.py", line 46, in _to_wkb
    from shapely.geos import WKBWriter, lgeos  # type: ignore
ImportError: cannot import name 'WKBWriter' from 'shapely.geos' (/home/airflow/.local/lib/python3.8/site-packages/shapely/geos.py)
[2024-07-28T10:56:29.437+0000] {processor.py:842} WARNING - No viable dags retrieved from /opt/airflow/dags/etl_dag.py
[2024-07-28T10:56:29.480+0000] {processor.py:183} INFO - Processing /opt/airflow/dags/etl_dag.py took 0.091 seconds
[2024-07-28T12:32:00.204+0000] {processor.py:161} INFO - Started process (PID=41067) to work on /opt/airflow/dags/etl_dag.py
[2024-07-28T12:32:00.206+0000] {processor.py:830} INFO - Processing file /opt/airflow/dags/etl_dag.py for tasks to queue
[2024-07-28T12:32:00.213+0000] {logging_mixin.py:188} INFO - [2024-07-28T12:32:00.213+0000] {dagbag.py:538} INFO - Filling up the DagBag from /opt/airflow/dags/etl_dag.py
[2024-07-28T12:32:00.230+0000] {logging_mixin.py:188} INFO - [2024-07-28T12:32:00.226+0000] {dagbag.py:348} ERROR - Failed to import: /opt/airflow/dags/etl_dag.py
Traceback (most recent call last):
  File "/home/airflow/.local/lib/python3.8/site-packages/airflow/models/dagbag.py", line 344, in parse
    loader.exec_module(new_module)
  File "<frozen importlib._bootstrap_external>", line 843, in exec_module
  File "<frozen importlib._bootstrap>", line 219, in _call_with_frames_removed
  File "/opt/airflow/dags/etl_dag.py", line 4, in <module>
    from airflow.providers.google.cloud.transfers.gcs_to_bigquery import GCSToBigQueryOperator
  File "/home/airflow/.local/lib/python3.8/site-packages/airflow/providers/google/cloud/transfers/gcs_to_bigquery.py", line 24, in <module>
    from airflow.providers.google.cloud.hooks.bigquery import BigQueryHook
  File "/home/airflow/.local/lib/python3.8/site-packages/airflow/providers/google/cloud/hooks/bigquery.py", line 33, in <module>
    from google.cloud.bigquery import (
  File "/home/airflow/.local/lib/python3.8/site-packages/google/cloud/bigquery/__init__.py", line 35, in <module>
    from google.cloud.bigquery.client import Client
  File "/home/airflow/.local/lib/python3.8/site-packages/google/cloud/bigquery/client.py", line 74, in <module>
    from google.cloud.bigquery import _pandas_helpers
  File "/home/airflow/.local/lib/python3.8/site-packages/google/cloud/bigquery/_pandas_helpers.py", line 56, in <module>
    _to_wkb = _to_wkb()
  File "/home/airflow/.local/lib/python3.8/site-packages/google/cloud/bigquery/_pandas_helpers.py", line 46, in _to_wkb
    from shapely.geos import WKBWriter, lgeos  # type: ignore
ImportError: cannot import name 'WKBWriter' from 'shapely.geos' (/home/airflow/.local/lib/python3.8/site-packages/shapely/geos.py)
[2024-07-28T12:32:00.231+0000] {processor.py:842} WARNING - No viable dags retrieved from /opt/airflow/dags/etl_dag.py
[2024-07-28T12:32:00.259+0000] {processor.py:183} INFO - Processing /opt/airflow/dags/etl_dag.py took 0.061 seconds
[2024-07-28T13:54:55.648+0000] {processor.py:161} INFO - Started process (PID=41072) to work on /opt/airflow/dags/etl_dag.py
[2024-07-28T13:54:55.649+0000] {processor.py:830} INFO - Processing file /opt/airflow/dags/etl_dag.py for tasks to queue
[2024-07-28T13:54:55.650+0000] {logging_mixin.py:188} INFO - [2024-07-28T13:54:55.650+0000] {dagbag.py:538} INFO - Filling up the DagBag from /opt/airflow/dags/etl_dag.py
[2024-07-28T13:54:55.663+0000] {logging_mixin.py:188} INFO - [2024-07-28T13:54:55.658+0000] {dagbag.py:348} ERROR - Failed to import: /opt/airflow/dags/etl_dag.py
Traceback (most recent call last):
  File "/home/airflow/.local/lib/python3.8/site-packages/airflow/models/dagbag.py", line 344, in parse
    loader.exec_module(new_module)
  File "<frozen importlib._bootstrap_external>", line 843, in exec_module
  File "<frozen importlib._bootstrap>", line 219, in _call_with_frames_removed
  File "/opt/airflow/dags/etl_dag.py", line 4, in <module>
    from airflow.providers.google.cloud.transfers.gcs_to_bigquery import GCSToBigQueryOperator
  File "/home/airflow/.local/lib/python3.8/site-packages/airflow/providers/google/cloud/transfers/gcs_to_bigquery.py", line 24, in <module>
    from airflow.providers.google.cloud.hooks.bigquery import BigQueryHook
  File "/home/airflow/.local/lib/python3.8/site-packages/airflow/providers/google/cloud/hooks/bigquery.py", line 33, in <module>
    from google.cloud.bigquery import (
  File "/home/airflow/.local/lib/python3.8/site-packages/google/cloud/bigquery/__init__.py", line 35, in <module>
    from google.cloud.bigquery.client import Client
  File "/home/airflow/.local/lib/python3.8/site-packages/google/cloud/bigquery/client.py", line 74, in <module>
    from google.cloud.bigquery import _pandas_helpers
  File "/home/airflow/.local/lib/python3.8/site-packages/google/cloud/bigquery/_pandas_helpers.py", line 56, in <module>
    _to_wkb = _to_wkb()
  File "/home/airflow/.local/lib/python3.8/site-packages/google/cloud/bigquery/_pandas_helpers.py", line 46, in _to_wkb
    from shapely.geos import WKBWriter, lgeos  # type: ignore
ImportError: cannot import name 'WKBWriter' from 'shapely.geos' (/home/airflow/.local/lib/python3.8/site-packages/shapely/geos.py)
[2024-07-28T13:54:55.664+0000] {processor.py:842} WARNING - No viable dags retrieved from /opt/airflow/dags/etl_dag.py
[2024-07-28T13:54:55.683+0000] {processor.py:183} INFO - Processing /opt/airflow/dags/etl_dag.py took 0.038 seconds
[2024-07-28T15:09:26.559+0000] {processor.py:161} INFO - Started process (PID=41077) to work on /opt/airflow/dags/etl_dag.py
[2024-07-28T15:09:26.562+0000] {processor.py:830} INFO - Processing file /opt/airflow/dags/etl_dag.py for tasks to queue
[2024-07-28T15:09:26.563+0000] {logging_mixin.py:188} INFO - [2024-07-28T15:09:26.562+0000] {dagbag.py:538} INFO - Filling up the DagBag from /opt/airflow/dags/etl_dag.py
[2024-07-28T15:09:26.582+0000] {logging_mixin.py:188} INFO - [2024-07-28T15:09:26.576+0000] {dagbag.py:348} ERROR - Failed to import: /opt/airflow/dags/etl_dag.py
Traceback (most recent call last):
  File "/home/airflow/.local/lib/python3.8/site-packages/airflow/models/dagbag.py", line 344, in parse
    loader.exec_module(new_module)
  File "<frozen importlib._bootstrap_external>", line 843, in exec_module
  File "<frozen importlib._bootstrap>", line 219, in _call_with_frames_removed
  File "/opt/airflow/dags/etl_dag.py", line 4, in <module>
    from airflow.providers.google.cloud.transfers.gcs_to_bigquery import GCSToBigQueryOperator
  File "/home/airflow/.local/lib/python3.8/site-packages/airflow/providers/google/cloud/transfers/gcs_to_bigquery.py", line 24, in <module>
    from airflow.providers.google.cloud.hooks.bigquery import BigQueryHook
  File "/home/airflow/.local/lib/python3.8/site-packages/airflow/providers/google/cloud/hooks/bigquery.py", line 33, in <module>
    from google.cloud.bigquery import (
  File "/home/airflow/.local/lib/python3.8/site-packages/google/cloud/bigquery/__init__.py", line 35, in <module>
    from google.cloud.bigquery.client import Client
  File "/home/airflow/.local/lib/python3.8/site-packages/google/cloud/bigquery/client.py", line 74, in <module>
    from google.cloud.bigquery import _pandas_helpers
  File "/home/airflow/.local/lib/python3.8/site-packages/google/cloud/bigquery/_pandas_helpers.py", line 56, in <module>
    _to_wkb = _to_wkb()
  File "/home/airflow/.local/lib/python3.8/site-packages/google/cloud/bigquery/_pandas_helpers.py", line 46, in _to_wkb
    from shapely.geos import WKBWriter, lgeos  # type: ignore
ImportError: cannot import name 'WKBWriter' from 'shapely.geos' (/home/airflow/.local/lib/python3.8/site-packages/shapely/geos.py)
[2024-07-28T15:09:26.583+0000] {processor.py:842} WARNING - No viable dags retrieved from /opt/airflow/dags/etl_dag.py
[2024-07-28T15:09:26.606+0000] {processor.py:183} INFO - Processing /opt/airflow/dags/etl_dag.py took 0.050 seconds
[2024-07-28T16:50:22.428+0000] {processor.py:161} INFO - Started process (PID=41082) to work on /opt/airflow/dags/etl_dag.py
[2024-07-28T16:50:22.430+0000] {processor.py:830} INFO - Processing file /opt/airflow/dags/etl_dag.py for tasks to queue
[2024-07-28T16:50:22.431+0000] {logging_mixin.py:188} INFO - [2024-07-28T16:50:22.431+0000] {dagbag.py:538} INFO - Filling up the DagBag from /opt/airflow/dags/etl_dag.py
[2024-07-28T16:50:22.453+0000] {logging_mixin.py:188} INFO - [2024-07-28T16:50:22.447+0000] {dagbag.py:348} ERROR - Failed to import: /opt/airflow/dags/etl_dag.py
Traceback (most recent call last):
  File "/home/airflow/.local/lib/python3.8/site-packages/airflow/models/dagbag.py", line 344, in parse
    loader.exec_module(new_module)
  File "<frozen importlib._bootstrap_external>", line 843, in exec_module
  File "<frozen importlib._bootstrap>", line 219, in _call_with_frames_removed
  File "/opt/airflow/dags/etl_dag.py", line 4, in <module>
    from airflow.providers.google.cloud.transfers.gcs_to_bigquery import GCSToBigQueryOperator
  File "/home/airflow/.local/lib/python3.8/site-packages/airflow/providers/google/cloud/transfers/gcs_to_bigquery.py", line 24, in <module>
    from airflow.providers.google.cloud.hooks.bigquery import BigQueryHook
  File "/home/airflow/.local/lib/python3.8/site-packages/airflow/providers/google/cloud/hooks/bigquery.py", line 33, in <module>
    from google.cloud.bigquery import (
  File "/home/airflow/.local/lib/python3.8/site-packages/google/cloud/bigquery/__init__.py", line 35, in <module>
    from google.cloud.bigquery.client import Client
  File "/home/airflow/.local/lib/python3.8/site-packages/google/cloud/bigquery/client.py", line 74, in <module>
    from google.cloud.bigquery import _pandas_helpers
  File "/home/airflow/.local/lib/python3.8/site-packages/google/cloud/bigquery/_pandas_helpers.py", line 56, in <module>
    _to_wkb = _to_wkb()
  File "/home/airflow/.local/lib/python3.8/site-packages/google/cloud/bigquery/_pandas_helpers.py", line 46, in _to_wkb
    from shapely.geos import WKBWriter, lgeos  # type: ignore
ImportError: cannot import name 'WKBWriter' from 'shapely.geos' (/home/airflow/.local/lib/python3.8/site-packages/shapely/geos.py)
[2024-07-28T16:50:22.454+0000] {processor.py:842} WARNING - No viable dags retrieved from /opt/airflow/dags/etl_dag.py
[2024-07-28T16:50:22.480+0000] {processor.py:183} INFO - Processing /opt/airflow/dags/etl_dag.py took 0.058 seconds
[2024-07-28T18:27:14.086+0000] {processor.py:161} INFO - Started process (PID=41087) to work on /opt/airflow/dags/etl_dag.py
[2024-07-28T18:27:14.089+0000] {processor.py:830} INFO - Processing file /opt/airflow/dags/etl_dag.py for tasks to queue
[2024-07-28T18:27:14.093+0000] {logging_mixin.py:188} INFO - [2024-07-28T18:27:14.093+0000] {dagbag.py:538} INFO - Filling up the DagBag from /opt/airflow/dags/etl_dag.py
[2024-07-28T18:27:14.102+0000] {logging_mixin.py:188} INFO - [2024-07-28T18:27:14.100+0000] {dagbag.py:348} ERROR - Failed to import: /opt/airflow/dags/etl_dag.py
Traceback (most recent call last):
  File "/home/airflow/.local/lib/python3.8/site-packages/airflow/models/dagbag.py", line 344, in parse
    loader.exec_module(new_module)
  File "<frozen importlib._bootstrap_external>", line 843, in exec_module
  File "<frozen importlib._bootstrap>", line 219, in _call_with_frames_removed
  File "/opt/airflow/dags/etl_dag.py", line 4, in <module>
    from airflow.providers.google.cloud.transfers.gcs_to_bigquery import GCSToBigQueryOperator
  File "/home/airflow/.local/lib/python3.8/site-packages/airflow/providers/google/cloud/transfers/gcs_to_bigquery.py", line 24, in <module>
    from airflow.providers.google.cloud.hooks.bigquery import BigQueryHook
  File "/home/airflow/.local/lib/python3.8/site-packages/airflow/providers/google/cloud/hooks/bigquery.py", line 33, in <module>
    from google.cloud.bigquery import (
  File "/home/airflow/.local/lib/python3.8/site-packages/google/cloud/bigquery/__init__.py", line 35, in <module>
    from google.cloud.bigquery.client import Client
  File "/home/airflow/.local/lib/python3.8/site-packages/google/cloud/bigquery/client.py", line 74, in <module>
    from google.cloud.bigquery import _pandas_helpers
  File "/home/airflow/.local/lib/python3.8/site-packages/google/cloud/bigquery/_pandas_helpers.py", line 56, in <module>
    _to_wkb = _to_wkb()
  File "/home/airflow/.local/lib/python3.8/site-packages/google/cloud/bigquery/_pandas_helpers.py", line 46, in _to_wkb
    from shapely.geos import WKBWriter, lgeos  # type: ignore
ImportError: cannot import name 'WKBWriter' from 'shapely.geos' (/home/airflow/.local/lib/python3.8/site-packages/shapely/geos.py)
[2024-07-28T18:27:14.105+0000] {processor.py:842} WARNING - No viable dags retrieved from /opt/airflow/dags/etl_dag.py
[2024-07-28T18:27:14.123+0000] {processor.py:183} INFO - Processing /opt/airflow/dags/etl_dag.py took 0.040 seconds
[2024-07-28T19:03:42.715+0000] {processor.py:161} INFO - Started process (PID=41092) to work on /opt/airflow/dags/etl_dag.py
[2024-07-28T19:03:42.717+0000] {processor.py:830} INFO - Processing file /opt/airflow/dags/etl_dag.py for tasks to queue
[2024-07-28T19:03:42.719+0000] {logging_mixin.py:188} INFO - [2024-07-28T19:03:42.718+0000] {dagbag.py:538} INFO - Filling up the DagBag from /opt/airflow/dags/etl_dag.py
[2024-07-28T19:03:42.760+0000] {logging_mixin.py:188} INFO - [2024-07-28T19:03:42.748+0000] {dagbag.py:348} ERROR - Failed to import: /opt/airflow/dags/etl_dag.py
Traceback (most recent call last):
  File "/home/airflow/.local/lib/python3.8/site-packages/airflow/models/dagbag.py", line 344, in parse
    loader.exec_module(new_module)
  File "<frozen importlib._bootstrap_external>", line 843, in exec_module
  File "<frozen importlib._bootstrap>", line 219, in _call_with_frames_removed
  File "/opt/airflow/dags/etl_dag.py", line 4, in <module>
    from airflow.providers.google.cloud.transfers.gcs_to_bigquery import GCSToBigQueryOperator
  File "/home/airflow/.local/lib/python3.8/site-packages/airflow/providers/google/cloud/transfers/gcs_to_bigquery.py", line 24, in <module>
    from airflow.providers.google.cloud.hooks.bigquery import BigQueryHook
  File "/home/airflow/.local/lib/python3.8/site-packages/airflow/providers/google/cloud/hooks/bigquery.py", line 33, in <module>
    from google.cloud.bigquery import (
  File "/home/airflow/.local/lib/python3.8/site-packages/google/cloud/bigquery/__init__.py", line 35, in <module>
    from google.cloud.bigquery.client import Client
  File "/home/airflow/.local/lib/python3.8/site-packages/google/cloud/bigquery/client.py", line 74, in <module>
    from google.cloud.bigquery import _pandas_helpers
  File "/home/airflow/.local/lib/python3.8/site-packages/google/cloud/bigquery/_pandas_helpers.py", line 56, in <module>
    _to_wkb = _to_wkb()
  File "/home/airflow/.local/lib/python3.8/site-packages/google/cloud/bigquery/_pandas_helpers.py", line 46, in _to_wkb
    from shapely.geos import WKBWriter, lgeos  # type: ignore
ImportError: cannot import name 'WKBWriter' from 'shapely.geos' (/home/airflow/.local/lib/python3.8/site-packages/shapely/geos.py)
[2024-07-28T19:03:42.761+0000] {processor.py:842} WARNING - No viable dags retrieved from /opt/airflow/dags/etl_dag.py
[2024-07-28T19:03:42.804+0000] {processor.py:183} INFO - Processing /opt/airflow/dags/etl_dag.py took 0.094 seconds
[2024-07-28T20:42:48.329+0000] {processor.py:161} INFO - Started process (PID=41097) to work on /opt/airflow/dags/etl_dag.py
[2024-07-28T20:42:48.331+0000] {processor.py:830} INFO - Processing file /opt/airflow/dags/etl_dag.py for tasks to queue
[2024-07-28T20:42:48.332+0000] {logging_mixin.py:188} INFO - [2024-07-28T20:42:48.331+0000] {dagbag.py:538} INFO - Filling up the DagBag from /opt/airflow/dags/etl_dag.py
[2024-07-28T20:42:48.345+0000] {logging_mixin.py:188} INFO - [2024-07-28T20:42:48.343+0000] {dagbag.py:348} ERROR - Failed to import: /opt/airflow/dags/etl_dag.py
Traceback (most recent call last):
  File "/home/airflow/.local/lib/python3.8/site-packages/airflow/models/dagbag.py", line 344, in parse
    loader.exec_module(new_module)
  File "<frozen importlib._bootstrap_external>", line 843, in exec_module
  File "<frozen importlib._bootstrap>", line 219, in _call_with_frames_removed
  File "/opt/airflow/dags/etl_dag.py", line 4, in <module>
    from airflow.providers.google.cloud.transfers.gcs_to_bigquery import GCSToBigQueryOperator
  File "/home/airflow/.local/lib/python3.8/site-packages/airflow/providers/google/cloud/transfers/gcs_to_bigquery.py", line 24, in <module>
    from airflow.providers.google.cloud.hooks.bigquery import BigQueryHook
  File "/home/airflow/.local/lib/python3.8/site-packages/airflow/providers/google/cloud/hooks/bigquery.py", line 33, in <module>
    from google.cloud.bigquery import (
  File "/home/airflow/.local/lib/python3.8/site-packages/google/cloud/bigquery/__init__.py", line 35, in <module>
    from google.cloud.bigquery.client import Client
  File "/home/airflow/.local/lib/python3.8/site-packages/google/cloud/bigquery/client.py", line 74, in <module>
    from google.cloud.bigquery import _pandas_helpers
  File "/home/airflow/.local/lib/python3.8/site-packages/google/cloud/bigquery/_pandas_helpers.py", line 56, in <module>
    _to_wkb = _to_wkb()
  File "/home/airflow/.local/lib/python3.8/site-packages/google/cloud/bigquery/_pandas_helpers.py", line 46, in _to_wkb
    from shapely.geos import WKBWriter, lgeos  # type: ignore
ImportError: cannot import name 'WKBWriter' from 'shapely.geos' (/home/airflow/.local/lib/python3.8/site-packages/shapely/geos.py)
[2024-07-28T20:42:48.348+0000] {processor.py:842} WARNING - No viable dags retrieved from /opt/airflow/dags/etl_dag.py
[2024-07-28T20:42:48.373+0000] {processor.py:183} INFO - Processing /opt/airflow/dags/etl_dag.py took 0.053 seconds
[2024-07-28T22:16:22.361+0000] {processor.py:161} INFO - Started process (PID=41104) to work on /opt/airflow/dags/etl_dag.py
[2024-07-28T22:16:22.365+0000] {processor.py:830} INFO - Processing file /opt/airflow/dags/etl_dag.py for tasks to queue
[2024-07-28T22:16:22.367+0000] {logging_mixin.py:188} INFO - [2024-07-28T22:16:22.366+0000] {dagbag.py:538} INFO - Filling up the DagBag from /opt/airflow/dags/etl_dag.py
[2024-07-28T22:16:22.395+0000] {logging_mixin.py:188} INFO - [2024-07-28T22:16:22.390+0000] {dagbag.py:348} ERROR - Failed to import: /opt/airflow/dags/etl_dag.py
Traceback (most recent call last):
  File "/home/airflow/.local/lib/python3.8/site-packages/airflow/models/dagbag.py", line 344, in parse
    loader.exec_module(new_module)
  File "<frozen importlib._bootstrap_external>", line 843, in exec_module
  File "<frozen importlib._bootstrap>", line 219, in _call_with_frames_removed
  File "/opt/airflow/dags/etl_dag.py", line 4, in <module>
    from airflow.providers.google.cloud.transfers.gcs_to_bigquery import GCSToBigQueryOperator
  File "/home/airflow/.local/lib/python3.8/site-packages/airflow/providers/google/cloud/transfers/gcs_to_bigquery.py", line 24, in <module>
    from airflow.providers.google.cloud.hooks.bigquery import BigQueryHook
  File "/home/airflow/.local/lib/python3.8/site-packages/airflow/providers/google/cloud/hooks/bigquery.py", line 33, in <module>
    from google.cloud.bigquery import (
  File "/home/airflow/.local/lib/python3.8/site-packages/google/cloud/bigquery/__init__.py", line 35, in <module>
    from google.cloud.bigquery.client import Client
  File "/home/airflow/.local/lib/python3.8/site-packages/google/cloud/bigquery/client.py", line 74, in <module>
    from google.cloud.bigquery import _pandas_helpers
  File "/home/airflow/.local/lib/python3.8/site-packages/google/cloud/bigquery/_pandas_helpers.py", line 56, in <module>
    _to_wkb = _to_wkb()
  File "/home/airflow/.local/lib/python3.8/site-packages/google/cloud/bigquery/_pandas_helpers.py", line 46, in _to_wkb
    from shapely.geos import WKBWriter, lgeos  # type: ignore
ImportError: cannot import name 'WKBWriter' from 'shapely.geos' (/home/airflow/.local/lib/python3.8/site-packages/shapely/geos.py)
[2024-07-28T22:16:22.397+0000] {processor.py:842} WARNING - No viable dags retrieved from /opt/airflow/dags/etl_dag.py
[2024-07-28T22:16:22.442+0000] {processor.py:183} INFO - Processing /opt/airflow/dags/etl_dag.py took 0.086 seconds
[2024-07-28T23:38:24.505+0000] {processor.py:161} INFO - Started process (PID=41109) to work on /opt/airflow/dags/etl_dag.py
[2024-07-28T23:38:24.507+0000] {processor.py:830} INFO - Processing file /opt/airflow/dags/etl_dag.py for tasks to queue
[2024-07-28T23:38:24.509+0000] {logging_mixin.py:188} INFO - [2024-07-28T23:38:24.509+0000] {dagbag.py:538} INFO - Filling up the DagBag from /opt/airflow/dags/etl_dag.py
[2024-07-28T23:38:24.537+0000] {logging_mixin.py:188} INFO - [2024-07-28T23:38:24.530+0000] {dagbag.py:348} ERROR - Failed to import: /opt/airflow/dags/etl_dag.py
Traceback (most recent call last):
  File "/home/airflow/.local/lib/python3.8/site-packages/airflow/models/dagbag.py", line 344, in parse
    loader.exec_module(new_module)
  File "<frozen importlib._bootstrap_external>", line 843, in exec_module
  File "<frozen importlib._bootstrap>", line 219, in _call_with_frames_removed
  File "/opt/airflow/dags/etl_dag.py", line 4, in <module>
    from airflow.providers.google.cloud.transfers.gcs_to_bigquery import GCSToBigQueryOperator
  File "/home/airflow/.local/lib/python3.8/site-packages/airflow/providers/google/cloud/transfers/gcs_to_bigquery.py", line 24, in <module>
    from airflow.providers.google.cloud.hooks.bigquery import BigQueryHook
  File "/home/airflow/.local/lib/python3.8/site-packages/airflow/providers/google/cloud/hooks/bigquery.py", line 33, in <module>
    from google.cloud.bigquery import (
  File "/home/airflow/.local/lib/python3.8/site-packages/google/cloud/bigquery/__init__.py", line 35, in <module>
    from google.cloud.bigquery.client import Client
  File "/home/airflow/.local/lib/python3.8/site-packages/google/cloud/bigquery/client.py", line 74, in <module>
    from google.cloud.bigquery import _pandas_helpers
  File "/home/airflow/.local/lib/python3.8/site-packages/google/cloud/bigquery/_pandas_helpers.py", line 56, in <module>
    _to_wkb = _to_wkb()
  File "/home/airflow/.local/lib/python3.8/site-packages/google/cloud/bigquery/_pandas_helpers.py", line 46, in _to_wkb
    from shapely.geos import WKBWriter, lgeos  # type: ignore
ImportError: cannot import name 'WKBWriter' from 'shapely.geos' (/home/airflow/.local/lib/python3.8/site-packages/shapely/geos.py)
[2024-07-28T23:38:24.538+0000] {processor.py:842} WARNING - No viable dags retrieved from /opt/airflow/dags/etl_dag.py
[2024-07-28T23:38:24.580+0000] {processor.py:183} INFO - Processing /opt/airflow/dags/etl_dag.py took 0.081 seconds
